<robot name="arm">
    <!--link name="world" /-->
    <!--joint name="base_joint" type="fixed">
        <origin xyz="0 0 0" rpy="0 0 0 " />
        <parent link="world" />
        <child link="base" />
    </joint-->
    <link name="base">
        <visual>
            <geometry>
                <mesh filename="package://arm_description/meshes/Base.dae" />
            </geometry>
        </visual>
        <collision>
            <geometry>
                <mesh filename="package://arm_description/meshes/Base.dae" />
            </geometry>
        </collision>

        <inertial>
            <mass value="2.664" />
            <inertia ixx="0.0123" iyy="0.0123" izz="0.0133" ixy="0.0" ixz="0.0" iyz="0.0" />
        </inertial>

    </link>
    <link name="link1">
        <visual>
            <geometry>
                <mesh filename="package://arm_description/meshes/Link1.dae" />
            </geometry>
        </visual>
        <collision>
            <geometry>
                <mesh filename="package://arm_description/meshes/Link1.dae" />
            </geometry>
        </collision>

        <inertial>
            <mass value="3.143" />
            <inertia ixx="0.1406" iyy="0.1401" izz="0.0045" ixy="0.0" ixz="0.0" iyz="0.0" />
        </inertial>

    </link>
    <link name="link2">
        <visual>
            <geometry>
                <mesh filename="package://arm_description/meshes/Link2.dae" />
            </geometry>
        </visual>
        <collision>
            <geometry>
                <mesh filename="package://arm_description/meshes/Link2.dae" />
            </geometry>
        </collision>

        <inertial>
            <mass value="4.621" />
            <inertia ixx="0.0069" iyy="0.2919" izz="0.2909" ixy="0.0" ixz="0.0" iyz="0.0" />
        </inertial>

    </link>
    <link name="link3">
        <visual>
            <geometry>
                <mesh filename="package://arm_description/meshes/Link3.dae" />
            </geometry>
        </visual>
        <collision>
            <geometry>
                <mesh filename="package://arm_description/meshes/Link3.dae" />
            </geometry>
        </collision>

        <inertial>
            <mass value="3.976" />
            <inertia ixx="0.0056" iyy="0.1810" izz="0.1805" ixy="0.0" ixz="0.0" iyz="0.0" />
        </inertial>

    </link>
    <link name="EE" />
    <joint name="joint1" type="revolute">
        <origin xyz="0 0 0.080" rpy="0 0 0 " />
        <limit lower="-3" upper="3" effort="30.0" velocity="6" />
        <parent link="base" />
        <child link="link1" />
        <axis xyz="0 0 1" />
        <safety_controller k_position="100.0" k_velocity="40.0" soft_lower_limit="-3" soft_upper_limit="3" />
    </joint>
    <joint name="joint2" type="revolute">
        <origin xyz="0.12 0 0.3" rpy="1.57 -1.57 1.57 " />
        <limit lower="-3" upper="3" effort="30.0" velocity="6" />
        <parent link="link1" />
        <child link="link2" />
        <axis xyz="0 0 1" />
        <safety_controller k_position="100.0" k_velocity="40.0" soft_lower_limit="-3" soft_upper_limit="3" />
    </joint>
    <joint name="joint3" type="revolute">
        <origin xyz="0.4 0 -.12" rpy="0 0 0 " />
        <limit lower="-3" upper="3" effort="30.0" velocity="6" />
        <parent link="link2" />
        <child link="link3" />
        <axis xyz="0 0 1" />
        <safety_controller k_position="100.0" k_velocity="40.0" soft_lower_limit="-3" soft_upper_limit="3" />
    </joint>
    <joint name="joint_EE" type="fixed">
        <origin xyz="0.4 0 0" rpy="0 0 0 " />
        <parent link="link3" />
        <child link="EE" />
    </joint>

    <transmission name="trans_joint1">
        <type>transmission_interface/SimpleTransmission</type>
        <joint name="joint1">
            <hardwareInterface>hardware_interface/EffortJointInterface</hardwareInterface>
        </joint>
        <actuator name="joint1_motor">
            <hardwareInterface>hardware_interface/EffortJointInterface</hardwareInterface>
            <mechanicalReduction>1</mechanicalReduction>
        </actuator>
    </transmission>
    <transmission name="trans_joint2">
        <type>transmission_interface/SimpleTransmission</type>
        <joint name="joint2">
            <hardwareInterface>hardware_interface/EffortJointInterface</hardwareInterface>
        </joint>
        <actuator name="joint2_motor">
            <hardwareInterface>hardware_interface/EffortJointInterface</hardwareInterface>
            <mechanicalReduction>1</mechanicalReduction>
        </actuator>
    </transmission>
    <transmission name="trans_joint3">
        <type>transmission_interface/SimpleTransmission</type>
        <joint name="joint3">
            <hardwareInterface>hardware_interface/EffortJointInterface</hardwareInterface>
        </joint>
        <actuator name="joint3_motor">
            <hardwareInterface>hardware_interface/EffortJointInterface</hardwareInterface>
            <mechanicalReduction>1</mechanicalReduction>
        </actuator>
    </transmission>
    <gazebo>
        <plugin name="gazebo_ros_control" filename="libgazebo_ros_control.so">
            <robotNamespace>/arm</robotNamespace>
        </plugin>
    </gazebo>
</robot>